2021-06-30 10:46:49,631 INFO: Microblog startup [in /Users/a/Project/microblog/app/__init__.py:(lineno)d]
2021-06-30 10:48:06,649 INFO: Microblog startup [in /Users/a/Project/microblog/app/__init__.py:(lineno)d]
2021-06-30 11:10:00,411 INFO: Microblog startup [in /Users/a/Project/microblog/app/__init__.py:(lineno)d]
2021-07-02 10:33:12,711 INFO: Microblog startup [in /Users/a/Project/microblog/app/__init__.py:68]
2021-07-02 10:33:16,122 ERROR: Exception on / [GET] [in /usr/local/lib/python3.9/site-packages/flask/app.py:1891]
Traceback (most recent call last):
  File "/usr/local/lib/python3.9/site-packages/flask/app.py", line 2447, in wsgi_app
    response = self.full_dispatch_request()
  File "/usr/local/lib/python3.9/site-packages/flask/app.py", line 1952, in full_dispatch_request
    rv = self.handle_user_exception(e)
  File "/usr/local/lib/python3.9/site-packages/flask/app.py", line 1821, in handle_user_exception
    reraise(exc_type, exc_value, tb)
  File "/usr/local/lib/python3.9/site-packages/flask/_compat.py", line 39, in reraise
    raise value
  File "/usr/local/lib/python3.9/site-packages/flask/app.py", line 1948, in full_dispatch_request
    rv = self.preprocess_request()
  File "/usr/local/lib/python3.9/site-packages/flask/app.py", line 2242, in preprocess_request
    rv = func()
  File "/Users/a/Project/microblog/app/main/routes.py", line 18, in before_request
    g.locale = str(get_locale())
  File "/usr/local/lib/python3.9/site-packages/flask_babel/__init__.py", line 226, in get_locale
    rv = babel.locale_selector_func()
  File "/Users/a/Project/microblog/app/__init__.py", line 76, in get_locale
    return request.accept_languages.best_match(app.config['LANGUAGES'])
NameError: name 'app' is not defined
2021-07-02 10:34:25,259 INFO: Microblog startup [in /Users/a/Project/microblog/app/__init__.py:68]
2021-07-02 10:34:27,091 ERROR: Exception on / [GET] [in /usr/local/lib/python3.9/site-packages/flask/app.py:1891]
Traceback (most recent call last):
  File "/usr/local/lib/python3.9/site-packages/flask/app.py", line 2447, in wsgi_app
    response = self.full_dispatch_request()
  File "/usr/local/lib/python3.9/site-packages/flask/app.py", line 1952, in full_dispatch_request
    rv = self.handle_user_exception(e)
  File "/usr/local/lib/python3.9/site-packages/flask/app.py", line 1821, in handle_user_exception
    reraise(exc_type, exc_value, tb)
  File "/usr/local/lib/python3.9/site-packages/flask/_compat.py", line 39, in reraise
    raise value
  File "/usr/local/lib/python3.9/site-packages/flask/app.py", line 1948, in full_dispatch_request
    rv = self.preprocess_request()
  File "/usr/local/lib/python3.9/site-packages/flask/app.py", line 2242, in preprocess_request
    rv = func()
  File "/Users/a/Project/microblog/app/main/routes.py", line 18, in before_request
    g.locale = str(get_locale())
  File "/usr/local/lib/python3.9/site-packages/flask_babel/__init__.py", line 230, in get_locale
    locale = Locale.parse(rv)
  File "/usr/local/lib/python3.9/site-packages/babel/core.py", line 268, in parse
    parts = parse_locale(identifier, sep=sep)
  File "/usr/local/lib/python3.9/site-packages/babel/core.py", line 1094, in parse_locale
    raise ValueError('expected only letters, got %r' % lang)
ValueError: expected only letters, got 'zh-cn'
2021-07-02 10:35:59,306 INFO: Microblog startup [in /Users/a/Project/microblog/app/__init__.py:68]
2021-07-02 10:36:01,181 ERROR: Exception on / [GET] [in /usr/local/lib/python3.9/site-packages/flask/app.py:1891]
Traceback (most recent call last):
  File "/usr/local/lib/python3.9/site-packages/flask/app.py", line 2447, in wsgi_app
    response = self.full_dispatch_request()
  File "/usr/local/lib/python3.9/site-packages/flask/app.py", line 1952, in full_dispatch_request
    rv = self.handle_user_exception(e)
  File "/usr/local/lib/python3.9/site-packages/flask/app.py", line 1821, in handle_user_exception
    reraise(exc_type, exc_value, tb)
  File "/usr/local/lib/python3.9/site-packages/flask/_compat.py", line 39, in reraise
    raise value
  File "/usr/local/lib/python3.9/site-packages/flask/app.py", line 1950, in full_dispatch_request
    rv = self.dispatch_request()
  File "/usr/local/lib/python3.9/site-packages/flask/app.py", line 1936, in dispatch_request
    return self.view_functions[rule.endpoint](**req.view_args)
  File "/usr/local/lib/python3.9/site-packages/flask_login/utils.py", line 272, in decorated_view
    return func(*args, **kwargs)
  File "/Users/a/Project/microblog/app/main/routes.py", line 38, in index
    page, current_app.config['POSTS_PER_PAGE'], False)
KeyError: 'POSTS_PER_PAGE'
2021-07-02 10:37:33,409 INFO: Microblog startup [in /Users/a/Project/microblog/app/__init__.py:68]
2021-07-02 10:37:35,217 ERROR: Exception on / [GET] [in /usr/local/lib/python3.9/site-packages/flask/app.py:1891]
Traceback (most recent call last):
  File "/usr/local/lib/python3.9/site-packages/flask/app.py", line 2447, in wsgi_app
    response = self.full_dispatch_request()
  File "/usr/local/lib/python3.9/site-packages/flask/app.py", line 1952, in full_dispatch_request
    rv = self.handle_user_exception(e)
  File "/usr/local/lib/python3.9/site-packages/flask/app.py", line 1821, in handle_user_exception
    reraise(exc_type, exc_value, tb)
  File "/usr/local/lib/python3.9/site-packages/flask/_compat.py", line 39, in reraise
    raise value
  File "/usr/local/lib/python3.9/site-packages/flask/app.py", line 1950, in full_dispatch_request
    rv = self.dispatch_request()
  File "/usr/local/lib/python3.9/site-packages/flask/app.py", line 1936, in dispatch_request
    return self.view_functions[rule.endpoint](**req.view_args)
  File "/usr/local/lib/python3.9/site-packages/flask_login/utils.py", line 272, in decorated_view
    return func(*args, **kwargs)
  File "/Users/a/Project/microblog/app/main/routes.py", line 41, in index
    return render_template('index.html', title=_('Home'), form=form,
  File "/usr/local/lib/python3.9/site-packages/flask/templating.py", line 137, in render_template
    return _render(
  File "/usr/local/lib/python3.9/site-packages/flask/templating.py", line 120, in _render
    rv = template.render(context)
  File "/usr/local/lib/python3.9/site-packages/jinja2/environment.py", line 1090, in render
    self.environment.handle_exception()
  File "/usr/local/lib/python3.9/site-packages/jinja2/environment.py", line 832, in handle_exception
    reraise(*rewrite_traceback_stack(source=source))
  File "/usr/local/lib/python3.9/site-packages/jinja2/_compat.py", line 28, in reraise
    raise value.with_traceback(tb)
  File "/Users/a/Project/microblog/app/templates/index.html", line 2, in top-level template code
    {% import 'bootstrap/wtf.html' as wtf %}
  File "/Users/a/Project/microblog/app/templates/base.html", line 1, in top-level template code
    {% extends 'bootstrap/base.html' %}
  File "/usr/local/lib/python3.9/site-packages/flask_bootstrap/templates/bootstrap/base.html", line 1, in top-level template code
    {% block doc -%}
  File "/usr/local/lib/python3.9/site-packages/flask_bootstrap/templates/bootstrap/base.html", line 3, in block "doc"
    <html{% block html_attribs %}{% endblock html_attribs %}>
  File "/usr/local/lib/python3.9/site-packages/flask_bootstrap/templates/bootstrap/base.html", line 11, in block "html"
    {%- endblock metas %}
  File "/usr/local/lib/python3.9/site-packages/flask_bootstrap/templates/bootstrap/base.html", line 12, in block "body"
  File "/Users/a/Project/microblog/app/templates/base.html", line 18, in block "navbar"
    <a class="navbar-brand" href="{{ url_for('index') }}">Microblog</a>
  File "/usr/local/lib/python3.9/site-packages/flask/helpers.py", line 370, in url_for
    return appctx.app.handle_url_build_error(error, endpoint, values)
  File "/usr/local/lib/python3.9/site-packages/flask/app.py", line 2216, in handle_url_build_error
    reraise(exc_type, exc_value, tb)
  File "/usr/local/lib/python3.9/site-packages/flask/_compat.py", line 39, in reraise
    raise value
  File "/usr/local/lib/python3.9/site-packages/flask/helpers.py", line 357, in url_for
    rv = url_adapter.build(
  File "/usr/local/lib/python3.9/site-packages/werkzeug/routing.py", line 2179, in build
    raise BuildError(endpoint, values, method, self)
werkzeug.routing.BuildError: Could not build url for endpoint 'index'. Did you mean 'main.index' instead?
2021-07-02 10:41:54,488 INFO: Microblog startup [in /Users/a/Project/microblog/app/__init__.py:68]
